Sourcing python-remove-tests-dir-hook
Sourcing python-catch-conflicts-hook.sh
Sourcing python-remove-bin-bytecode-hook.sh
Sourcing pip-build-hook
Using pipBuildPhase
Using pipShellHook
Sourcing pip-install-hook
Using pipInstallPhase
Sourcing python-imports-check-hook.sh
Using pythonImportsCheckPhase
Sourcing python-namespaces-hook
Sourcing flit-build-hook
@nix { "action": "setPhase", "phase": "unpackPhase" }
unpacking sources
unpacking source archive /nix/store/14kjlipxbfjpsn1hsjrq6x05l7a9mgry-exceptiongroup-1.0.0rc7.tar.gz
source root is exceptiongroup-1.0.0rc7
setting SOURCE_DATE_EPOCH to timestamp 1653080396 of file exceptiongroup-1.0.0rc7/src/exceptiongroup/_version.py
@nix { "action": "setPhase", "phase": "patchPhase" }
patching sources
Removing path dependencies
Finished removing path dependencies
Removing git dependencies
Finished removing git dependencies
@nix { "action": "setPhase", "phase": "configurePhase" }
configuring
no configure script, doing nothing
@nix { "action": "setPhase", "phase": "buildPhase" }
building
Executing pipBuildPhase
Creating a wheel...
WARNING: The directory '/homeless-shelter/.cache/pip' or its parent directory is not owned or is not writable by the current user. The cache has been disabled. Check the permissions and owner of that directory. If executing pip wit>
Processing /build/exceptiongroup-1.0.0rc7
  Running command Preparing metadata (pyproject.toml)
  Preparing metadata (pyproject.toml) ... done
ERROR: Exception:
Traceback (most recent call last):
  File "/nix/store/xsf0zqc9c3xkmbd7zdi8k6p3yi5qqy12-python3.9-pip-22.0.4/lib/python3.9/site-packages/pip/_internal/cli/base_command.py", line 167, in exc_logging_wrapper
    status = run_func(*args)
  File "/nix/store/xsf0zqc9c3xkmbd7zdi8k6p3yi5qqy12-python3.9-pip-22.0.4/lib/python3.9/site-packages/pip/_internal/cli/req_command.py", line 205, in wrapper
    return func(self, options, args)
  File "/nix/store/xsf0zqc9c3xkmbd7zdi8k6p3yi5qqy12-python3.9-pip-22.0.4/lib/python3.9/site-packages/pip/_internal/commands/wheel.py", line 145, in run
    requirement_set = resolver.resolve(reqs, check_supported_wheels=True)
  File "/nix/store/xsf0zqc9c3xkmbd7zdi8k6p3yi5qqy12-python3.9-pip-22.0.4/lib/python3.9/site-packages/pip/_internal/resolution/resolvelib/resolver.py", line 75, in resolve
    collected = self.factory.collect_root_requirements(root_reqs)
  File "/nix/store/xsf0zqc9c3xkmbd7zdi8k6p3yi5qqy12-python3.9-pip-22.0.4/lib/python3.9/site-packages/pip/_internal/resolution/resolvelib/factory.py", line 506, in collect_root_requirements
    req = self._make_requirement_from_install_req(
  File "/nix/store/xsf0zqc9c3xkmbd7zdi8k6p3yi5qqy12-python3.9-pip-22.0.4/lib/python3.9/site-packages/pip/_internal/resolution/resolvelib/factory.py", line 468, in _make_requirement_from_install_req
    cand = self._make_candidate_from_link(
  File "/nix/store/xsf0zqc9c3xkmbd7zdi8k6p3yi5qqy12-python3.9-pip-22.0.4/lib/python3.9/site-packages/pip/_internal/resolution/resolvelib/factory.py", line 215, in _make_candidate_from_link
    self._link_candidate_cache[link] = LinkCandidate(
  File "/nix/store/xsf0zqc9c3xkmbd7zdi8k6p3yi5qqy12-python3.9-pip-22.0.4/lib/python3.9/site-packages/pip/_internal/resolution/resolvelib/candidates.py", line 288, in __init__
    super().__init__(
  File "/nix/store/xsf0zqc9c3xkmbd7zdi8k6p3yi5qqy12-python3.9-pip-22.0.4/lib/python3.9/site-packages/pip/_internal/resolution/resolvelib/candidates.py", line 158, in __init__
    self.dist = self._prepare()
  File "/nix/store/xsf0zqc9c3xkmbd7zdi8k6p3yi5qqy12-python3.9-pip-22.0.4/lib/python3.9/site-packages/pip/_internal/resolution/resolvelib/candidates.py", line 227, in _prepare
    dist = self._prepare_distribution()
  File "/nix/store/xsf0zqc9c3xkmbd7zdi8k6p3yi5qqy12-python3.9-pip-22.0.4/lib/python3.9/site-packages/pip/_internal/resolution/resolvelib/candidates.py", line 299, in _prepare_distribution
    return preparer.prepare_linked_requirement(self._ireq, parallel_builds=True)
  File "/nix/store/xsf0zqc9c3xkmbd7zdi8k6p3yi5qqy12-python3.9-pip-22.0.4/lib/python3.9/site-packages/pip/_internal/operations/prepare.py", line 487, in prepare_linked_requirement
    return self._prepare_linked_requirement(req, parallel_builds)
  File "/nix/store/xsf0zqc9c3xkmbd7zdi8k6p3yi5qqy12-python3.9-pip-22.0.4/lib/python3.9/site-packages/pip/_internal/operations/prepare.py", line 556, in _prepare_linked_requirement
    dist = _get_prepared_distribution(
  File "/nix/store/xsf0zqc9c3xkmbd7zdi8k6p3yi5qqy12-python3.9-pip-22.0.4/lib/python3.9/site-packages/pip/_internal/operations/prepare.py", line 58, in _get_prepared_distribution
    abstract_dist.prepare_distribution_metadata(finder, build_isolation)
  File "/nix/store/xsf0zqc9c3xkmbd7zdi8k6p3yi5qqy12-python3.9-pip-22.0.4/lib/python3.9/site-packages/pip/_internal/distributions/sdist.py", line 47, in prepare_distribution_metadata
    self.req.prepare_metadata()
  File "/nix/store/xsf0zqc9c3xkmbd7zdi8k6p3yi5qqy12-python3.9-pip-22.0.4/lib/python3.9/site-packages/pip/_internal/req/req_install.py", line 522, in prepare_metadata
    self.metadata_directory = generate_metadata(
  File "/nix/store/xsf0zqc9c3xkmbd7zdi8k6p3yi5qqy12-python3.9-pip-22.0.4/lib/python3.9/site-packages/pip/_internal/operations/build/metadata.py", line 35, in generate_metadata
    distinfo_dir = backend.prepare_metadata_for_build_wheel(metadata_dir)
  File "/nix/store/xsf0zqc9c3xkmbd7zdi8k6p3yi5qqy12-python3.9-pip-22.0.4/lib/python3.9/site-packages/pip/_vendor/pep517/wrappers.py", line 188, in prepare_metadata_for_build_wheel
    return self._call_hook('prepare_metadata_for_build_wheel', {
  File "/nix/store/xsf0zqc9c3xkmbd7zdi8k6p3yi5qqy12-python3.9-pip-22.0.4/lib/python3.9/site-packages/pip/_vendor/pep517/wrappers.py", line 332, in _call_hook
    raise BackendUnavailable(data.get('traceback', ''))
pip._vendor.pep517.wrappers.BackendUnavailable: Traceback (most recent call last):
  File "/nix/store/xsf0zqc9c3xkmbd7zdi8k6p3yi5qqy12-python3.9-pip-22.0.4/lib/python3.9/site-packages/pip/_vendor/pep517/in_process/_in_process.py", line 89, in _build_backend
    obj = import_module(mod_path)
  File "/nix/store/wnrc4daqbd6v5ifqlxsj75ky8556zy0p-python3-3.9.12/lib/python3.9/importlib/__init__.py", line 127, in import_module
    return _bootstrap._gcd_import(name[level:], package, level)
  File "<frozen importlib._bootstrap>", line 1030, in _gcd_import
  File "<frozen importlib._bootstrap>", line 1007, in _find_and_load
  File "<frozen importlib._bootstrap>", line 984, in _find_and_load_unlocked
ModuleNotFoundError: No module named 'flit_scm'
